Workbook

Sheet Ответы
B1: нужно цифру "1" поставить в клетку "Да" или "Нет" на каждое утверждение
C2: код | D2: 1234567890
B3: Утверждения, относящиеся ко мне (моему характеру) | C3: № | D3: Да | E3: Нет
B4: 1. Иногда мне в голову приходят такие мысли, что лучше никому о них не рассказывать. | C4: 1 | D4: 1 | F4: =SUM(D4:E4) -> 1
B5: 2. Я охотно принимаю участие во всех собраниях и других общественных мероприятиях. | C5: 2 | D5: 1 | F5: =SUM(D5:E5) -> 1
B6: 3. Часто какая-нибудь навязчивая мысль не дает мне заснуть. | C6: 3 | E6: 1 | F6: =SUM(D6:E6) -> 1
B7: 4. Временами у меня бывают приступы смеха или плача, с которыми я никак не могу справиться. | C7: 4 | E7: 1 | F7: =SUM(D7:E7) -> 1
B8: 5. Я сильно теряюсь, оказавшись неожиданно в центр внимания. | C8: 5 | E8: 1 | F8: =SUM(D8:E8) -> 1
B9: 6. Бывали случаи, что я не сдерживал своих обещаний. | C9: 6 | D9: 1 | F9: =SUM(D9:E9) -> 1
B10: 7. Критика, в том виде, в котором ее осуществляют многие люди, скорее выбивают меня из колеи, чем помогают. | C10: 7 | E10: 1 | F10: =SUM(D10:E10) -> 1
B11: 8. У меня часто болит голова. | C11: 8 | E11: 1 | F11: =SUM(D11:E11) -> 1
B12: 9. Если мое удачное замечание осталось незамеченным, я его не повторяю. | C12: 9 | E12: 1 | F12: =SUM(D12:E12) -> 1
B13: 10. Часто я склонен мысленно возвращаться к своим неприятностям, и мне трудно выбросить их из головы. | C13: 10 | E13: 1 | F13: =SUM(D13:E13) -> 1
B14: 11. Иногда я говорю неправду. | C14: 11 | D14: 1 | F14: =SUM(D14:E14) -> 1
B15: 12. В компании я чувствую себя неловко и из-за этого произвожу впечатление хуже, чем мог бы. | C15: 12 | E15: 1 | F15: =SUM(D15:E15) -> 1
B16: 13. Мне бывает трудно заснуть из-за беспокойства по поводу неудачи. | C16: 13 | E16: 1 | F16: =SUM(D16:E16) -> 1
B17: 14. Вставая утром, я часто чувствую себя усталым и разбитым. | C17: 14 | E17: 1 | F17: =SUM(D17:E17) -> 1
B18: 15. Раз в неделю или чаще я безо всякой видимой причины внезапно ощущаю жар во всем теле. | C18: 15 | E18: 1 | F18: =SUM(D18:E18) -> 1
B19: 16. Мне бывает трудно изложить свои мысли словами, поэтому я редко включаюсь в беседу. | C19: 16 | E19: 1 | F19: =SUM(D19:E19) -> 1
B20: 17. Бывает, что меня беспокоит чувство вины или угрызения совести и-за какого-нибудь пустяка. | C20: 17 | E20: 1 | F20: =SUM(D20:E20) -> 1
B21: 18. Бывало, что я говорил о вещах, в которых не разбираюсь. | C21: 18 | D21: 1 | F21: =SUM(D21:E21) -> 1
B22: 19. Бывает, что я передаю слухи. | C22: 19 | D22: 1 | F22: =SUM(D22:E22) -> 1
B23: 20. У меня бывают очень странные и необычные внутренние переживания. | C23: 20 | E23: 1 | F23: =SUM(D23:E23) -> 1
B24: 21. Уходя из дома, я часто беспокоюсь о том, что нужно сделать сегодня. | C24: 21 | E24: 1 | F24: =SUM(D24:E24) -> 1
B25: 22. Бывает, что у меня без особой причины кружится голова. | C25: 22 | E25: 1 | F25: =SUM(D25:E25) -> 1
B26: 23. Бывает, что я откладываю на завтра то, что нужно сделать сегодня. | C26: 23 | D26: 1 | F26: =SUM(D26:E26) -> 1
B27: 24. Я смущаюсь вступить в спор даже по хорошо известному мне вопросу. | C27: 24 | E27: 1 | F27: =SUM(D27:E27) -> 1
B28: 25. Я чрезмерно чувствителен и легко раним. | C28: 25 | E28: 1 | F28: =SUM(D28:E28) -> 1
B29: 26. Бывало, что я невежливо разговаривал с родителями | C29: 26 | D29: 1 | F29: =SUM(D29:E29) -> 1
B30: 27. Иногда, когда я неважно себя чувствую, я бываю раздражительными. | C30: 27 | D30: 1 | F30: =SUM(D30:E30) -> 1
B31: 28. Мне, безусловно, не хватает уверенности в себе. | C31: 28 | E31: 1 | F31: =SUM(D31:E31) -> 1
B32: 29. Я часто упускаю возможность из-за своей внутренней нерешительности. | C32: 29 | E32: 1 | F32: =SUM(D32:E32) -> 1
B33: 30. Я довольно безразличен к тому, что со мной будет. | C33: 30 | E33: 1 | F33: =SUM(D33:E33) -> 1
B34: 31. Я всегда выполняю то, что мне говорят старшие. | C34: 31 | D34: 1 | F34: =SUM(D34:E34) -> 1
B35: 32. Я остро и длительно переживаю неудачи. | C35: 32 | E35: 1 | F35: =SUM(D35:E35) -> 1
B36: 33. Я склонен принимать все слишком близко к сердцу. | C36: 33 | E36: 1 | F36: =SUM(D36:E36) -> 1
B37: 34. Иногда я хвалю себя. | C37: 34 | D37: 1 | F37: =SUM(D37:E37) -> 1
B38: 35. Я считаю, что моя семейная жизнь такая же хорошая, как и у большинства моих знакомых. | C38: 35 | D38: 1 | F38: =SUM(D38:E38) -> 1
B39: 36. Я часто чувствую себя одиноким и никому ненужным. | C39: 36 | E39: 1 | F39: =SUM(D39:E39) -> 1
B40: 37. Временами я уверен в своей бесполезности. | C40: 37 | E40: 1 | F40: =SUM(D40:E40) -> 1
...

Sheet Шкала
D3: Isk | E3: Con | F3: Ast | G3: Ist | H3: Psi | I3: NPN
B4: 1. Иногда мне в голову приходят такие нехорошие мысли, что лучше никому о них не рассказывать. | C4: 1 | D4: =IF(Ответы!E4=1,1,0) -> 0
B5: 2. Я охотно принимаю участие во всех собраниях и других общественных мероприятиях. | C5: 2 | D5: =IF(Ответы!D5=1,1,0) -> 1
B6: 3. Часто какая-нибудь навязчивая мысль не дает мне заснуть. | C6: 3 | F6: =IF(Ответы!D6=1,1,0) -> 0
B7: 4. Временами у меня бывают приступы смеха или плача, с которыми я никак не могу справиться. | C7: 4 | E7: =IF(Ответы!D7=1,1,0) -> 0 | G7: =IF(Ответы!D7=1,1,0) -> 0 | I7: =IF(Ответы!D7=1,1,0) -> 0
B8: 5. Я сильно теряюсь, оказавшись неожиданно в центр внимания. | C8: 5 | F8: =IF(Ответы!D8=1,1,0) -> 0
B9: 6. Бывали случаи, что я не сдерживал своих обещаний. | C9: 6 | D9: =IF(Ответы!E9=1,1,0) -> 0
B10: 7. Критика, в том виде, в котором ее осуществляют многие люди, скорее выбивают меня из колеи, чем помогают. | C10: 7 | F10: =IF(Ответы!D10=1,1,0) -> 0
B11: 8. У меня часто болит голова. | C11: 8 | I11: =IF(Ответы!D11=1,1,0) -> 0
B12: 9. Если мое удачное замечание осталось незамеченным, я его не повторяю. | C12: 9 | F12: =IF(Ответы!D12=1,1,0) -> 0
B13: 10. Часто я склонен мысленно возвращаться к своим неприятностям, и мне трудно выбросить их из головы. | C13: 10 | F13: =IF(Ответы!D13=1,1,0) -> 0 | I13: =IF(Ответы!D13=1,1,0) -> 0
B14: 11. Иногда я говорю неправду. | C14: 11 | D14: =IF(Ответы!E14=1,1,0) -> 0
B15: 12. В компании я чувствую себя неловко и из-за этого произвожу впечатление хуже, чем мог бы. | C15: 12 | F15: =IF(Ответы!D15=1,1,0) -> 0
B16: 13. Мне бывает трудно заснуть из-за беспокойства по поводу неудачи. | C16: 13 | F16: =IF(Ответы!D16=1,1,0) -> 0
B17: 14. Вставая утром, я часто чувствую себя усталым и разбитым. | C17: 14 | F17: =IF(Ответы!D17=1,1,0) -> 0
B18: 15. Раз в неделю или чаще я безо всякой видимой причины внезапно ощущаю жар во всем теле. | C18: 15 | I18: =IF(Ответы!D18=1,1,0) -> 0
B19: 16. Мне бывает трудно изложить свои мысли словами, поэтому я редко включаюсь в беседу. | C19: 16 | F19: =IF(Ответы!D19=1,1,0) -> 0
B20: 17. Бывает, что меня беспокоит чувство вины или угрызения совести и-за какого-нибудь пустяка. | C20: 17 | F20: =IF(Ответы!D20=1,1,0) -> 0
B21: 18. Бывало, что я говорил о вещах, в которых не разбираюсь. | C21: 18 | D21: =IF(Ответы!E21=1,1,0) -> 0
B22: 19. Бывает, что я передаю слухи. | C22: 19 | D22: =IF(Ответы!E22=1,1,0) -> 0
B23: 20. У меня бывают очень странные и необычные внутренние переживания. | C23: 20 | E23: =IF(Ответы!D23=1,1,0) -> 0 | F23: =IF(Ответы!D23=1,1,0) -> 0 | I23: =IF(Ответы!D23=1,1,0) -> 0
B24: 21. Уходя из дома, я часто беспокоюсь о том, что нужно сделать сегодня. | C24: 21 | F24: =IF(Ответы!D24=1,1,0) -> 0
B25: 22. Бывает, что у меня без особой причины кружится голова. | C25: 22 | I25: =IF(Ответы!D25=1,1,0) -> 0
B26: 23. Бывает, что я откладываю на завтра то, что нужно сделать сегодня. | C26: 23 | D26: =IF(Ответы!E26=1,1,0) -> 0
B27: 24. Я смущаюсь вступить в спор даже по хорошо известному мне вопросу. | C27: 24 | F27: =IF(Ответы!D27=1,1,0) -> 0
B28: 25. Я чрезмерно чувствителен и легко раним. | C28: 25 | I28: =IF(Ответы!D28=1,1,0) -> 0
B29: 26. Бывало, что я невежливо разговаривал с родителями | C29: 26 | D29: =IF(Ответы!E29=1,1,0) -> 0
B30: 27. Иногда, когда я неважно себя чувствую, я бываю раздражительными. | C30: 27 | D30: =IF(Ответы!E30=1,1,0) -> 0
B31: 28. Мне, безусловно, не хватает уверенности в себе. | C31: 28 | F31: =IF(Ответы!D31=1,1,0) -> 0
B32: 29. Я часто упускаю возможность из-за своей внутренней нерешительности. | C32: 29 | F32: =IF(Ответы!D32=1,1,0) -> 0
B33: 30. Я довольно безразличен к тому, что со мной будет. | C33: 30 | E33: =IF(Ответы!D33=1,1,0) -> 0 | I33: =IF(Ответы!D33=1,1,0) -> 0
B34: 31. Я всегда выполняю то, что мне говорят старшие. | C34: 31 | D34: =IF(Ответы!D34=1,1,0) -> 1
B35: 32. Я остро и длительно переживаю неудачи. | C35: 32 | F35: =IF(Ответы!D35=1,1,0) -> 0 | I35: =IF(Ответы!D35=1,1,0) -> 0
B36: 33. Я склонен принимать все слишком близко к сердцу. | C36: 33 | F36: =IF(Ответы!D36=1,1,0) -> 0 | I36: =IF(Ответы!D36=1,1,0) -> 0
B37: 34. Иногда я хвалю себя. | C37: 34 | D37: =IF(Ответы!E37=1,1,0) -> 0
B38: 35. Я считаю, что моя семейная жизнь такая же хорошая, как и у большинства моих знакомых. | C38: 35 | I38: =IF(Ответы!E38=1,1,0) -> 0
B39: 36. Я часто чувствую себя одиноким и никому ненужным. | C39: 36 | E39: =IF(Ответы!D39=1,1,0) -> 0 | F39: =IF(Ответы!D39=1,1,0) -> 0 | I39: =IF(Ответы!D39=1,1,0) -> 0
B40: 37. Временами я уверен в своей бесполезности. | C40: 37 | F40: =IF(Ответы!D40=1,1,0) -> 0 | I40: =IF(Ответы!D40=1,1,0) -> 0
B41: 38. Мне часто говорят, что я вспыльчив. | C41: 38 | I41: =IF(Ответы!D41=1,1,0) -> 0
B42: 39. В игре я предпочитаю выигрывать. | C42: 39 | D42: =IF(Ответы!E42=1,1,0) -> 0
...

Sheet Резюме
A2: Условные обозначения (названия шкал тестов):
A3: Л – шкала лжи («социальной желательности») норма: от 0 до 9; если выше – недостаточная достоверность (рекомендуется ретест через 2 недели);
A4: Кон – контрольные вопросы на склонность с аутоагрессии норма: до 6 (из 14)
A5: НПН – нервно-писхической неустойчивости; норма : от 0 до 23 балла – для реком.; общее число вопросов – 67.
A6: Пп – психопатии ш. (вероятность неадекватой реакции на стимул); норма от 0 до 13 (из 30);
A7: Ист – истероидность ; норма от 0 до 27 (из 30)
A8: Па – психастении шкала; норма: от 0 до 15 (из 19)
D11: База выходная:
D13: дата
D14: код | E14: =Ответы!D2 -> 1234567890
D15: возраст
D16: Пол
D18: Достоверность | E18: не достоверен | F18: (внимание: при суммировании ответ на первый вопрос не учитывается) | H18: 0 | J18: > 9 | K18: не достоверен
D19: Аутоагрессия | E19: -
D20: Нервно-психическая устойчивость | E20: -
D21: Психопатическая реакция | E21: -
D22: Истероидные проявления | E22: -
D23: Ранимость, чувствительность | E23: -
D25: или
C27: Isk | D27: Достоверность | E27: =CONCATENATE(LEFT(Шкала!D165,2)," из 15") -> 4 из 15 | F27: (внимание: при суммировании ответ на первый вопрос не учитывается) | G27: 0-9 | H27: 1 | J27: норма
C28: Con | D28: Аутоагрессия | E28: =CONCATENATE(LEFT(Шкала!E165,2)," из 14") -> 0 из 14 | G28: 6-8 | H28: 2 | J28: условно рекомендован | L28: > 8 | M28: нереомендован
C29: NPN | D29: Нервно-психическая устойчивость | E29: =CONCATENATE(LEFT(Шкала!I165,2)," из 67") -> 2 из 67 | G29: 23-30 | H29: 3 | J29: условно рекомендован | L29: > 30 | M29: нереомендован
C30: Psi | D30: Психопатическая реакция | E30: =CONCATENATE(LEFT(Шкала!H165,2)," из 30") -> 3 из 30 | H30: 4 | L30: > 13 | M30: нереомендован
C31: Ist | D31: Истероидные проявления | E31: =CONCATENATE(LEFT(Шкала!G165,2)," из 30") -> 1 из 30 | G31: 27-30 | H31: 5 | J31: условно рекомендован
C32: Ast | D32: Ранимость, чувствительность | E32: =CONCATENATE(LEFT(Шкала!F165,2)," из 19") -> 0 из 19 | G32: 15-19 | H32: 6 | J32: условно рекомендован
H34: варианты
D35: резюме | F35: (ретест, рекомендован, нерекомендован, условно рекомендован) | H35: a | I35: Л | J35: > 9 | K35: ретест
H36: b | I36: Кон | J36: > 9 | K36: нереомендован
H37: c | I37: НПН | J37: > 30 | K37: нереомендован
H38: d | I38: Пп | J38: > 13 | K38: нереомендован
H39: e | J39: норма
H40: f | J40: условно рекомендован
D42: Для каждого
D45: Дата
D46: Код | E46: 1234567890
D47: Возраст
D48: Пол
D50: Достоверность | F50: достоверность N% или недостоверен
D51: Аутоагрессия | F51: низкая (норма), средняя, высокая
D52: Нервно-психическая устойчивость | F52: высокая (норма), средняя, низкая
...
